Workbook
Name X: 'CAMPOS DE INGRESO DML'!$K$4

Sheet CAMPOS DE INGRESO RAYPAC
A1: CAMPOS DE INGRESO RAYPAC
A2: N° | B2: FECHA DE RECEPCIÓN | C2: REPARACIÓN/PRESUPUESTO | D2: CLIENTE | E2: N° DE SERIE | F2: MODELO DE MÁQUINA | G2: TIPO DE MÁQUINA | H2: N° DE BATERÍA | I2: N° DE CARGADOR | J2: DIAGNÓSTICO DE INGRESO | K2: COMERCIAL RESPONSABLE | L2: MAIL DE COMERCIAL RESPONSABLE | M2: N° DE REMITO
A3: 1 | B3: 45885 | C3: REPARACIÓN | D3: BAYER | E3: 24000052 | F3: ITA24 | G3: A BATERIA | H3: NO APLICA | I3: NO APLICA | J3: NO SELLA | K3: Ezequiel Pacheco | L3: ezequiel.pacheco@raypac.net | M3: 2561 | R3: CT20 | S3: NO APLICA | T3: ABBOTT | U3: REPARACIÓN
R4: CT25 | T4: ALUAR | U4: PRESUPUESTO
P5: Ezequiel Pacheco | Q5: ezequiel.pacheco@raypac.net | R5: CT40 | S5: A BATERIA | T5: ANDREANI
P6: Leonardo Gastager | Q6: leonardo.gastager@raypac.net | R6: CTT20 | S6: MANUAL | T6: BAYER
P7: Luciana Gregorio | Q7: luciana.gregorio@raypac.net | R7: CTT25 | S7: NEUMÁTICA | T7: Cartocor
P8: Luciana Paradiso | Q8: luciana.paradiso@raypac.net | R8: CTT40 | S8: OTRO | T8: CASTELLI
A9: Dato correlativo partiendo del N° 1 de forma automática | B9: Acá va la fecha, si el sistema esta en hora debe sugerir la fecha del día | C9: ELEGIR DEL DESPLEGABLE | D9: Nombre del cliente | E9: Ingreso manual del N° de serie de la maquina | F9: Elegir del desplegable el modelo de máquina | G9: Elegir según desplegable | H9: Colocar el número de bateria manualmente o bien elegir la opción NO APLICA | I9: Colocar el número de cargador manualmente o bien elegir la opción NO APLICA | J9: Ingreso manual de diagnostico con el que llega la máquina a RAYPAC de acuerdo a la información que brinda el cliente | K9: Acá se selecciona del desplegable | L9: Acá se selecciona del desplegable o bien se relaciona segun el nombre asociado al comercial que se elige de forma automática | M9: Cuando Raypac va a enviar la máquina a Service debe cargar el N° de remito de envío | P9: Daniela Sofio | Q9: daniela.sofio@raypac.net | R9: ITA10 | T9: CONARCO
P10: Hernán Rivero | Q10: hernan.rivero@raypac.net | R10: ITA11 | T10: CYKLOP
P11: Matias Chaubell | Q11: matias.chaubell@raypac.net | R11: ITA12 | T11: DERIPLOM
P12: Paola Isanelli | Q12: paola.isabelli@raypac.net | R12: ITA20 | T12: EGGER
P13: Romina Gamarra | Q13: romina.gamarra@raypac.net | R13: ITA21 | T13: FAMIQ
R14: ITA24 | T14: FLAMIA
R15: ITA25 | T15: GEMEZ
T16: GENERAL PLASTICS
F17: LA INFORMACIÓN SE PUEDE EDITAR LAS VECES QUE FUERA NECESARIO, PEO SIEMPRE DEBE VOLVER A GRABASRSE AL FINALIZAR | T17: HENKEL ARG.
T18: HIDRO ARG
K19: LA INFORMACIÓNQUEDA FREEZADA Y YA NO SE PODRÁ EDITAR DE FORMA DIRECTA, PARA EDITAR SE DEBERÁ INGRESAR UN CODIGO O CONTRASEÑA DE DESPLOBUEO. | T19: HILADOS S.A.
T20: ILVA
T21: INDUSTRIAS LEAR
T22: JL
T23: LA ELENENSE
T24: LA MORALEJA
T25: M.DON DAVID
T26: MABXINCE
T27: MECALUX
T28: MESUCAN
T29: NUTRIN
T30: ONTEC FORTINOX
T31: PILKINTON
... T41: VITOPEL

Sheet CAMPOS DE INGRESO DML
A1: FICHA | B1: 500 | C1: CAMPOS DE INGRESO DML
A2: FECHA DE INGRESO A DML | B2: TÉCNICO | C2: ESTADO GENERAL | E2: OBSERVACIÓN | F2: DIAGNÓSTICO DE REPARACIÓN | G2: REPUESTOS COLOCADOS | L2: MECANIZADO | M2: HORAS ADICIONALES | N2: HORAS ADICIONALES | O2: ESTADO | P2: N° DE CICLOS | Q2: FECHA DE EGRESO | R2: N° DE REMITO DML
A3: 45891 | B3: RICARDO | C3: PARTES DEL EQUIPO | D3: ESTADO | E3: MAQUINA CON VARIOS DETALLES | F3: REPUESTOS COLOCADOS | G3: CÓDIGO | H3: DESCRIPCIÓN | I3: CANTIDAD | J3: EN STOCK | K3: EN FALTA | L3: NO APLICA | N3: NO APLICA | O3: A LA ESPERA DE REVISIÓN | P3: 10200 | Q3: 45894 | R3: 258 | T3: NO APLICA | U3: NO APLICA | V3: NO APLICA | W3: NO APLICA | X3: NO APLICA | Y3: NO APLICA | Z3: NO APLICA | AA3: NO APLICA | AB3: NO APLICA | AC3: NO APLICA | AD3: A LA ESPERA DE REPUESTOS | AE3: NO APLICA | AG3: RICARDO
C4: ESTADO DEL EQUIPO | D4: BUENO | G4: D006120 | H4: =IF(G4="","",VLOOKUP(G4,'MATRIZ DE REPUESTOS '!$A$2:$B$231,2,FALSE)) -> WEAR PLATE | I4: 1 | J4: TRUE | T4: BUENO | U4: BUENO | V4: CON TORNILLOS FALTANTES | W4: CON TORNILLOS FALTANTES | X4: OK | Y4: A PROBAR | Z4: CON DIENTES FALTANTES | AA4: A PROBAR | AB4: DESGASTADO | AC4: DESGASTADO | AD4: A LA ESPERA DE REVISIÓN | AG4: DAVID
C5: CARCAZA | D5: CON TORNILLOS FALTANTES | G5: A000180 | H5: =IF(G5="","",VLOOKUP(G5,'MATRIZ DE REPUESTOS '!$A$2:$B$231,2,FALSE)) -> WELDING GROUP ASSEMBLED | I5: 1 | T5: EXCELENTE | U5: CON TORNILLOS FALTANTES | V5: FALTANTE | W5: GOLPEADO | X5: ROTO | Y5: FUNCIONAMIENTO OK | Z5: DESGASTADA | AA5: FALTANTE | AB5: FALTANTE | AC5: FALTANTE | AD5: EN REPARACIÓN
C6: CUBRE FEEDWHEEL | D6: FALTANTE | G6: B500273 | H6: =IF(G6="","",VLOOKUP(G6,'MATRIZ DE REPUESTOS '!$A$2:$B$231,2,FALSE)) -> SCREW TCEI M3X10 UNI 5931 | I6: 2 | T6: MALO | U6: EXCELENTE | V6: GOLPEADO | W6: OK | X6: SIN FUNCIONAR | Y6: NO FUNCIONA | Z6: FALTANTE | AA6: OK | AB6: OK | AC6: OK | AD6: MÁQUINA ENTREGADA
C7: MANGO | D7: OK | H7: =IF(G7="","",VLOOKUP(G7,'MATRIZ DE REPUESTOS '!$A$2:$B$231,2,FALSE)) | T7: OK | U7: MALO | V7: OK | W7: RAJADO | Z7: OK | AA7: ROTO | AC7: ROTO | AD7: MÁQUINA LISTA PARA RETIRAR
C8: BOTONES | D8: OK | H8: =IF(G8="","",VLOOKUP(G8,'MATRIZ DE REPUESTOS '!$A$2:$B$231,2,FALSE)) | T8: REGULAR | U8: OK | V8: RAJADO | W8: ROTO | Z8: ROTA | AA8: TRABADO
C9: MOTOR DE ARRASTRE | D9: A PROBAR | H9: =IF(G9="","",VLOOKUP(G9,'MATRIZ DE REPUESTOS '!$A$2:$B$231,2,FALSE)) | U9: RAJADA | V9: ROTO | Z9: SIN FILO
C10: MOTOR DE SELLADO | D10: A PROBAR | H10: =IF(G10="","",VLOOKUP(G10,'MATRIZ DE REPUESTOS '!$A$2:$B$231,2,FALSE)) | U10: REGULAR
C11: CUCHILLA | D11: DESGASTADA | H11: =IF(G11="","",VLOOKUP(G11,'MATRIZ DE REPUESTOS '!$A$2:$B$231,2,FALSE)) | U11: ROTA
C12: SERVO | D12: A PROBAR | H12: =IF(G12="","",VLOOKUP(G12,'MATRIZ DE REPUESTOS '!$A$2:$B$231,2,FALSE))
C13: RUEDA DE ARRASTRE | D13: OK | H13: =IF(G13="","",VLOOKUP(G13,'MATRIZ DE REPUESTOS '!$A$2:$B$231,2,FALSE))
C14: RESORTE DE MANIJA | D14: OK | H14: =IF(G14="","",VLOOKUP(G14,'MATRIZ DE REPUESTOS '!$A$2:$B$231,2,FALSE))
C15: OTROS | H15: =IF(G15="","",VLOOKUP(G15,'MATRIZ DE REPUESTOS '!$A$2:$B$231,2,FALSE))
B20: TÉCNICO RESPONSIBLE | C20: LISTA DE ESTADO PREFIJADO | D20: ELEGIR DEL DESPLEGABLE | E20: INGRESO MANUAL DE TEXTO | F20: INGRESO MANUAL DE TEXTO | G20: CODIGO DE PRODUCTO hasta 15, en el ejemplo sólo hay 12 | H20: NOMBRTE DEL PRODUCTO LLAMADO SE DEBE TRAER EL NOMBRE DE LA MATRIZ | I20: ingreso manual de cantidad de cada repuesto | J20: Si esta en stock aparece el tilde verde | K20: Si no esta en stock aparece la cruz roja y desaparece el verde | L20: Acá se escribe tipo de mecanizado realizado y si tiene costo, caso contrario se debe poder seleccionar NO APLICA | M20: Acá se escribe se ponen la cantidad de horas adicionales si las hubiese, caso contrario se debe poder seleccionar NO APLICA | N20: Aca se debe poder poner las horas adicionales si las hay y si no la opcíon NO APLICA | O20: Seleccionar del desplegable el estado actual de la máquina | Q20: Fecha de salida de DML | R20: N° REMITO CARGA MANUAL
K27: CUANDO SE ELIJA LA OPCIÓN DE MÁQUINA LISTA PARA ENTREGAR SE HABILITA EL BOTÓN DE FINALIZAR REPARACIÓN Y LA INFO QUEDARÁ FREEZADA, SOLO SE PODRA RE-EDITAR INGRESANDO ALGUN CODIGO O CONTRASEÑA DE DESBLOQUEO. AL FINALIZAR LA REPARACIÓN Y UNA VEZ QUE YA NO HAYA QUE EDITAR NADA MÁS, SE PODRÁ OPRIMIR EL BOTÓN DE GENERACIÓN DE FICHA, LA CUAL SE PODRA IMPRIMIR Y A LA VEZ DISPARARÁ EL CORREO AVISANDO QUE LA MÁQUINA SE ENCUENTRA LISTA JUNTO AL ENVÍO DE FICHA AL CORREO AL COMERCIAL CARGADO POR RAYPAC
E28: LA INFORMACIÓN SE PUEDE EDITAR LAS VECES QUE FUERA NECESARIO, UNA VEZ GENERADO EL TICKET SE HABILITAN LAS CASILLAS RESTANTES Y SE PUEDE DAR COMIENZO A LA REPARACIÓN. LA GENERACIÓN DE TICKET DISPARA LA POSIBILIDAD DE IMPRESIÓN DE TICKET Y EL ENVÍO POR CORREO AL COMERCIAL DE RAYPAC CARGADO POR ELLOS.

Sheet MATRIZ DE REPUESTOS 
A1: CODIGO | B1: ITEM
A2: A000006 | B2: HT TENSION MOTOR GROUP
A3: A000007 | B3: LT TENSION MOTOR GROUP
A4: A000038 | B4: WELDING GROUP
A5: A000062 | B5: CUTTER (ITA 40)
A6: A000097 | B6: SIGNALS CARD WITH LIGHT TRANSP
A7: A000155 | B7: SUSPENSION HOOK ITA40-24-25
A8: A000177 | B8: ITA25 TENSION MOTOR GROUP
A9: A000178 | B9: ITA24 TENSION MOTOR GROUP
A10: A000179 | B10: CONNECTING ROD ASS.Y
A11: A000180 | B11: WELDING GROUP ASSEMBLED
A12: A000181 | B12: EXCENTRIC SHAFT ASSEMB.
... A231: GCTT40 | B231: GANCHOS CTT40

Sheet FICHA
G1: INFORME DML SOBRE EL EQUIPO EN REVISION
A2: Nº Ficha
A3: ='CAMPOS DE INGRESO DML'!B1 -> 500 | B3: Servicio Técnico
A7: Fecha de recepción Raypac: | C7: ='CAMPOS DE INGRESO RAYPAC'!B3 -> 45885 | G7: ESTADO DEL EQUIPO | I7: ='CAMPOS DE INGRESO DML'!D4 -> BUENO
G8: CARCAZA | I8: ='CAMPOS DE INGRESO DML'!D5 -> CON TORNILLOS FALTANTES
A9: Comercial responsanle: | C9: ='CAMPOS DE INGRESO RAYPAC'!K3 -> Ezequiel Pacheco | G9: CUBRE FEEDWHEEL | I9: ='CAMPOS DE INGRESO DML'!D6 -> FALTANTE
G10: MANGO | I10: ='CAMPOS DE INGRESO DML'!D7 -> OK
A11: Nombre del Cliente: | C11: ='CAMPOS DE INGRESO RAYPAC'!D3 -> BAYER | G11: BOTONES | I11: ='CAMPOS DE INGRESO DML'!D8 -> OK
G12: MOTOR DE ARRASTRE | I12: ='CAMPOS DE INGRESO DML'!D9 -> A PROBAR
A13: Equipo Recibido: | C13: ='CAMPOS DE INGRESO RAYPAC'!F3 -> ITA24 | D13: Serie N°: | E13: ='CAMPOS DE INGRESO RAYPAC'!E3 -> 24000052 | G13: MOTOR DE SELLADO | I13: ='CAMPOS DE INGRESO DML'!D10 -> A PROBAR
G14: CUCHILLA | I14: ='CAMPOS DE INGRESO DML'!D11 -> DESGASTADA
A15: Fecha de ingreso DML: | C15: ='CAMPOS DE INGRESO DML'!A3 -> 45891 | D15: Bat N°: | E15: ='CAMPOS DE INGRESO RAYPAC'!H3 -> NO APLICA | G15: SERVO | I15: ='CAMPOS DE INGRESO DML'!D12 -> A PROBAR
G16: RUEDA DE ARRASTRE | I16: ='CAMPOS DE INGRESO DML'!D13 -> OK
A17: Fecha de egreso DML: | C17: ='CAMPOS DE INGRESO DML'!Q3 -> 45894 | D17: Cargador N°: | E17: ='CAMPOS DE INGRESO RAYPAC'!I3 -> NO APLICA | G17: RESORTE DE MANIJA | I17: ='CAMPOS DE INGRESO DML'!D14 -> OK
G18: OTROS | I18: ='CAMPOS DE INGRESO DML'!D15 -> 0
A19: DIAGNOSTICO DEL DEPARTAMENTO TECNICO
A20: ='CAMPOS DE INGRESO RAYPAC'!J3 -> NO SELLA
A24: OBSERVACIONES
A25: ='CAMPOS DE INGRESO DML'!E3 -> MAQUINA CON VARIOS DETALLES
A38: DIAGNOSTICO DE REPARACIÓN
A39: ='CAMPOS DE INGRESO DML'!F3 -> REPUESTOS COLOCADOS
A47: REPUESTOS COLOCADOS
A48: Cantidad | B48: Codigo | C48: DESCRIPCION | D48: EN STOCK | E48: EN FALTA
A49: ='CAMPOS DE INGRESO DML'!I4 -> 1 | B49: ='CAMPOS DE INGRESO DML'!G4 -> D006120 | C49: ='CAMPOS DE INGRESO DML'!H4 -> WEAR PLATE | D49: TRUE
A50: ='CAMPOS DE INGRESO DML'!I5 -> 1 | B50: ='CAMPOS DE INGRESO DML'!G5 -> A000180 | C50: ='CAMPOS DE INGRESO DML'!H5 -> WELDING GROUP ASSEMBLED | D50: TRUE
A51: ='CAMPOS DE INGRESO DML'!I6 -> 2 | B51: ='CAMPOS DE INGRESO DML'!G6 -> B500273 | C51: ='CAMPOS DE INGRESO DML'!H6 -> SCREW TCEI M3X10 UNI 5931 | D51: TRUE
A52: ='CAMPOS DE INGRESO DML'!I7 -> 0 | B52: ='CAMPOS DE INGRESO DML'!G7 -> 0 | C52: ='CAMPOS DE INGRESO DML'!H7 | D52: TRUE
A53: ='CAMPOS DE INGRESO DML'!I8 -> 0 | B53: ='CAMPOS DE INGRESO DML'!G8 -> 0 | C53: ='CAMPOS DE INGRESO DML'!H8 | D53: TRUE
A54: ='CAMPOS DE INGRESO DML'!I9 -> 0 | B54: ='CAMPOS DE INGRESO DML'!G9 -> 0 | C54: ='CAMPOS DE INGRESO DML'!H9 | D54: TRUE
A55: ='CAMPOS DE INGRESO DML'!I10 -> 0 | B55: ='CAMPOS DE INGRESO DML'!G10 -> 0 | C55: ='CAMPOS DE INGRESO DML'!H10 | D55: TRUE
A56: ='CAMPOS DE INGRESO DML'!I11 -> 0 | B56: ='CAMPOS DE INGRESO DML'!G11 -> 0 | C56: ='CAMPOS DE INGRESO DML'!H11 | D56: TRUE
A57: ='CAMPOS DE INGRESO DML'!I12 -> 0 | B57: ='CAMPOS DE INGRESO DML'!G12 -> 0 | C57: ='CAMPOS DE INGRESO DML'!H12 | D57: TRUE
A58: ='CAMPOS DE INGRESO DML'!I13 -> 0 | B58: ='CAMPOS DE INGRESO DML'!G13 -> 0 | C58: ='CAMPOS DE INGRESO DML'!H13 | D58: TRUE
A59: ='CAMPOS DE INGRESO DML'!I14 -> 0 | B59: ='CAMPOS DE INGRESO DML'!G14 -> 0 | C59: ='CAMPOS DE INGRESO DML'!H14 | D59: TRUE
A60: ='CAMPOS DE INGRESO DML'!I15 -> 0 | B60: ='CAMPOS DE INGRESO DML'!G15 -> 0 | C60: ='CAMPOS DE INGRESO DML'!H15 | D60: TRUE
A62: N° DE CICLOS DE LA MÁQUINA CON LAS QUE SALE DE ST | D62: ='CAMPOS DE INGRESO DML'!P3 -> 10200
A64: MARCAR CON UNA CRUZ LO QUE CORRESPONDA
A65: TIPO DE MAQUINA QUE INGRESO AL ST | D65: ='CAMPOS DE INGRESO RAYPAC'!G3 -> A BATERIA
A66: El módulo reparación Base es de tres (3hs)
A67: HORAS ADICIONALES DE TRABAJO | D67: ='CAMPOS DE INGRESO DML'!N3 -> NO APLICA
...
